Workbook

Sheet Campaign Metadata
A1: Campaign_Name | B1: Start_Date | C1: End_Date | D1: Objective | E1: Total_Budget | F1: Target_Platforms | G1: Primary_Hashtags
A2: SummerBeats | B2: 45458 | C2: 45488 | D2: Brand Awareness | E2: 175000 | F2: Instagram,YouTube | G2: #SpotifyWrapped,#MusicForEveryone
A3: Wrapped2024 | B3: 45627 | C3: 45657 | D3: Engagement | E3: 225000 | F3: Twitter,YouTube | G3: #SpotifyWrapped,#NowPlaying
A4: ChillVibes | B4: 45667 | C4: 45698 | D4: Product Launch | E4: 200000 | F4: Instagram,Twitter | G4: #ChillVibes,#SoundtrackOfLife
A5: IndieWave | B5: 45717 | C5: 45747 | D5: Traffic | E5: 160000 | F5: Facebook,Instagram | G5: #DiscoverWeekly,#IndieWave

Sheet Cleaned Post
A1: Post ID | B1: Platform | C1: Date | D1: Campaign Phase | E1: Content Type | F1: Post Text | G1: Likes | H1: Shares | I1: Comments | J1: Impressions | K1: Reach | L1: Clicks | M1: Engagment Rate | N1: Total Engagment | O1: Campaign_Name | P1: Hashtags Used1 | Q1: hastags used1
A2: SP001 | B2: Instagram | C2: 45781 | D2: =IF( C2 < _xlfn.XLOOKUP(O2,'Campaign Metadata'!A:A,'Campaign Metadata'!B:B), "Before", IF( C2 <= _xlfn.XLOOKUP(O2,'Campaign Metadata'!A:A,'Campaign Metadata'!C:C), "During", "After" ) ) -> After | E2: Text | F2: Discover fresh beats on Spotify! | G2: 2414 | H2: 245 | I2: 137 | J2: 21181 | K2: 45292 | L2: 133 | M2: =(G2 +I2 +H2) / J2 -> 0.1320051 | N2: =G2+H2+I2 -> 2796 | O2: ChillVibes | P2: #SoundtrackOfLife | Q2: #NowPlaying
A3: SP002 | B3: Instagram | C3: 45689 | D3: =IF( C3 < _xlfn.XLOOKUP(O3,'Campaign Metadata'!A:A,'Campaign Metadata'!B:B), "Before", IF( C3 <= _xlfn.XLOOKUP(O3,'Campaign Metadata'!A:A,'Campaign Metadata'!C:C), "During", "After" ) ) -> Before | E3: Text | F3: Explore the latest podcasts now. | G3: 1934 | H3: 210 | I3: 393 | J3: 29129 | K3: 73287 | L3: 273 | M3: =(G3 +I3 +H3) / J3 -> 0.087095335 | N3: =G3+H3+I3 -> 2537 | O3: IndieWave | P3: #DiscoverWeekly
A4: SP003 | B4: Twitter | C4: 45629 | D4: =IF( C4 < _xlfn.XLOOKUP(O4,'Campaign Metadata'!A:A,'Campaign Metadata'!B:B), "Before", IF( C4 <= _xlfn.XLOOKUP(O4,'Campaign Metadata'!A:A,'Campaign Metadata'!C:C), "During", "After" ) ) -> Before | E4: Story | F4: New music just dropped. Hit play! | G4: 3092 | H4: 177 | I4: 81 | J4: 47533 | K4: 29220 | L4: 121 | M4: =(G4 +I4 +H4) / J4 -> 0.070477353 | N4: =G4+H4+I4 -> 3350 | O4: ChillVibes | P4: #MusicForEveryone | Q4: #NowPlaying
A5: SP004 | B5: Instagram | C5: 45629 | D5: =IF( C5 < _xlfn.XLOOKUP(O5,'Campaign Metadata'!A:A,'Campaign Metadata'!B:B), "Before", IF( C5 <= _xlfn.XLOOKUP(O5,'Campaign Metadata'!A:A,'Campaign Metadata'!C:C), "During", "After" ) ) -> Before | E5: Text | F5: Wrapped is here! Relive your top tracks ðŸŽ§ | G5: 3173 | H5: 229 | I5: 197 | J5: 29604 | K5: 21809 | L5: 272 | M5: =(G5 +I5 +H5) / J5 -> 0.12157141 | N5: =G5+H5+I5 -> 3599 | O5: ChillVibes | P5: #SoundtrackOfLife | Q5: #NowPlaying
A6: SP005 | B6: YouTube | C6: 45388 | D6: =IF( C6 < _xlfn.XLOOKUP(O6,'Campaign Metadata'!A:A,'Campaign Metadata'!B:B), "Before", IF( C6 <= _xlfn.XLOOKUP(O6,'Campaign Metadata'!A:A,'Campaign Metadata'!C:C), "During", "After" ) ) -> Before | E6: Text | F6: Music that moves youâ€”only on Spotify. | G6: 2748 | H6: 145 | I6: 315 | J6: 24401 | K6: 61182 | L6: 200 | M6: =(G6 +I6 +H6) / J6 -> 0.13147002 | N6: =G6+H6+I6 -> 3208 | O6: IndieWave | P6: #DiscoverWeekly | Q6: #SpotifyWrapped
A7: SP006 | B7: YouTube | C7: 45456 | D7: =IF( C7 < _xlfn.XLOOKUP(O7,'Campaign Metadata'!A:A,'Campaign Metadata'!B:B), "Before", IF( C7 <= _xlfn.XLOOKUP(O7,'Campaign Metadata'!A:A,'Campaign Metadata'!C:C), "During", "After" ) ) -> Before | E7: Text | F7: Whatâ€™s your vibe today? #SpotifyHits | G7: 3882 | H7: 239 | I7: 275 | J7: 58748 | K7: 44646 | L7: 149 | M7: =(G7 +I7 +H7) / J7 -> 0.074828079 | N7: =G7+H7+I7 -> 4396 | O7: IndieWave | P7: #DiscoverWeekly | Q7: #SpotifyWrapped
A8: SP007 | B8: Twitter | C8: 45645 | D8: =IF( C8 < _xlfn.XLOOKUP(O8,'Campaign Metadata'!A:A,'Campaign Metadata'!B:B), "Before", IF( C8 <= _xlfn.XLOOKUP(O8,'Campaign Metadata'!A:A,'Campaign Metadata'!C:C), "During", "After" ) ) -> Before | E8: Story | F8: Get into the groove with our new drop! | G8: 4674 | H8: 409 | I8: 327 | J8: 20756 | K8: 63599 | L8: 212 | M8: =(G8 +I8 +H8) / J8 -> 0.26064752 | N8: =G8+H8+I8 -> 5410 | O8: ChillVibes | P8: #SoundtrackOfLife | Q8: #NowPlaying
A9: SP008 | B9: Twitter | C9: 45421 | D9: =IF( C9 < _xlfn.XLOOKUP(O9,'Campaign Metadata'!A:A,'Campaign Metadata'!B:B), "Before", IF( C9 <= _xlfn.XLOOKUP(O9,'Campaign Metadata'!A:A,'Campaign Metadata'!C:C), "During", "After" ) ) -> Before | E9: Story | F9: Wrapped is here! Relive your top tracks ðŸŽ§ | G9: 1428 | H9: 347 | I9: 67 | J9: 21148 | K9: 19712 | L9: 120 | M9: =(G9 +I9 +H9) / J9 -> 0.087100435 | N9: =G9+H9+I9 -> 1842 | O9: ChillVibes | P9: #DiscoverWeekly | Q9: #MusicForEveryone
A10: SP009 | B10: Twitter | C10: 45823 | D10: =IF( C10 < _xlfn.XLOOKUP(O10,'Campaign Metadata'!A:A,'Campaign Metadata'!B:B), "Before", IF( C10 <= _xlfn.XLOOKUP(O10,'Campaign Metadata'!A:A,'Campaign Metadata'!C:C), "During", "After" ) ) -> After | E10: Text | F10: Top trending tracks updated daily! | G10: 4432 | H10: 223 | I10: 299 | J10: 59016 | K10: 21742 | L10: 171 | M10: =(G10 +I10 +H10) / J10 -> 0.083943337 | N10: =G10+H10+I10 -> 4954 | O10: ChillVibes | P10: #NowPlaying
A11: SP010 | B11: Twitter | C11: 45630 | D11: =IF( C11 < _xlfn.XLOOKUP(O11,'Campaign Metadata'!A:A,'Campaign Metadata'!B:B), "Before", IF( C11 <= _xlfn.XLOOKUP(O11,'Campaign Metadata'!A:A,'Campaign Metadata'!C:C), "During", "After" ) ) -> Before | E11: Text | F11: Wrapped is here! Relive your top tracks ðŸŽ§ | G11: 2357 | H11: 274 | I11: 172 | J11: 21566 | K11: 66829 | L11: 284 | M11: =(G11 +I11 +H11) / J11 -> 0.12997311 | N11: =G11+H11+I11 -> 2803 | O11: ChillVibes | P11: #NowPlaying
A12: SP011 | B12: Twitter | C12: 45357 | D12: =IF( C12 < _xlfn.XLOOKUP(O12,'Campaign Metadata'!A:A,'Campaign Metadata'!B:B), "Before", IF( C12 <= _xlfn.XLOOKUP(O12,'Campaign Metadata'!A:A,'Campaign Metadata'!C:C), "During", "After" ) ) -> Before | E12: Text | F12: Discover fresh beats on Spotify! | G12: 1971 | H12: 370 | I12: 306 | J12: 31316 | K12: 27897 | L12: 88 | M12: =(G12 +I12 +H12) / J12 -> 0.084525482 | N12: =G12+H12+I12 -> 2647 | O12: IndieWave | P12: #SoundtrackOfLife
A13: SP012 | B13: Instagram | C13: 45426 | D13: =IF( C13 < _xlfn.XLOOKUP(O13,'Campaign Metadata'!A:A,'Campaign Metadata'!B:B), "Before", IF( C13 <= _xlfn.XLOOKUP(O13,'Campaign Metadata'!A:A,'Campaign Metadata'!C:C), "During", "After" ) ) -> Before | E13: Text | F13: Discover fresh beats on Spotify! | G13: 1485 | H13: 353 | I13: 244 | J13: 38419 | K13: 38556 | L13: 86 | M13: =(G13 +I13 +H13) / J13 -> 0.054191936 | N13: =G13+H13+I13 -> 2082 | O13: ChillVibes | P13: #SoundtrackOfLife | Q13: #NowPlaying
A14: SP013 | B14: Twitter | C14: 45826 | D14: =IF( C14 < _xlfn.XLOOKUP(O14,'Campaign Metadata'!A:A,'Campaign Metadata'!B:B), "Before", IF( C14 <= _xlfn.XLOOKUP(O14,'Campaign Metadata'!A:A,'Campaign Metadata'!C:C), "During", "After" ) ) -> After | E14: Story | F14: Discover fresh beats on Spotify! | G14: 3956 | H14: 319 | I14: 61 | J14: 58162 | K14: 28720 | L14: 213 | M14: =(G14 +I14 +H14) / J14 -> 0.074550394 | N14: =G14+H14+I14 -> 4336 | O14: ChillVibes | P14: #MusicForEveryone | Q14: #NowPlaying
A15: SP014 | B15: Twitter | C15: 45573 | D15: =IF( C15 < _xlfn.XLOOKUP(O15,'Campaign Metadata'!A:A,'Campaign Metadata'!B:B), "Before", IF( C15 <= _xlfn.XLOOKUP(O15,'Campaign Metadata'!A:A,'Campaign Metadata'!C:C), "During", "After" ) ) -> Before | E15: Text | F15: From pop to podcasts, itâ€™s all here. | G15: 2460 | H15: 409 | I15: 253 | J15: 36702 | K15: 46122 | L15: 264 | M15: =(G15 +I15 +H15) / J15 -> 0.085063484 | N15: =G15+H15+I15 -> 3122 | O15: ChillVibes | P15: #NowPlaying
A16: SP015 | B16: Twitter | C16: 45418 | D16: =IF( C16 < _xlfn.XLOOKUP(O16,'Campaign Metadata'!A:A,'Campaign Metadata'!B:B), "Before", IF( C16 <= _xlfn.XLOOKUP(O16,'Campaign Metadata'!A:A,'Campaign Metadata'!C:C), "During", "After" ) ) -> Before | E16: Text | F16: Your weekend playlist is waiting. | G16: 3476 | H16: 355 | I16: 396 | J16: 37492 | K16: 27285 | L16: 179 | M16: =(G16 +I16 +H16) / J16 -> 0.11274405 | N16: =G16+H16+I16 -> 4227 | O16: ChillVibes | P16: #NowPlaying
A17: SP016 | B17: Twitter | C17: 45655 | D17: =IF( C17 < _xlfn.XLOOKUP(O17,'Campaign Metadata'!A:A,'Campaign Metadata'!B:B), "Before", IF( C17 <= _xlfn.XLOOKUP(O17,'Campaign Metadata'!A:A,'Campaign Metadata'!C:C), "During", "After" ) ) -> Before | E17: Story | F17: New music just dropped. Hit play! | G17: 4049 | H17: 377 | I17: 94 | J17: 48182 | K17: 42875 | L17: 172 | M17: =(G17 +I17 +H17) / J17 -> 0.093810967 | N17: =G17+H17+I17 -> 4520 | O17: ChillVibes | P17: #MusicForEveryone | Q17: #NowPlaying
A18: SP017 | B18: Twitter | C18: 45453 | D18: =IF( C18 < _xlfn.XLOOKUP(O18,'Campaign Metadata'!A:A,'Campaign Metadata'!B:B), "Before", IF( C18 <= _xlfn.XLOOKUP(O18,'Campaign Metadata'!A:A,'Campaign Metadata'!C:C), "During", "After" ) ) -> Before | E18: Text | F18: Whatâ€™s your vibe today? #SpotifyHits | G18: 1514 | H18: 164 | I18: 275 | J18: 41364 | K18: 44389 | L18: 83 | M18: =(G18 +I18 +H18) / J18 -> 0.04721497 | N18: =G18+H18+I18 -> 1953 | O18: ChillVibes | P18: #NowPlaying
A19: SP018 | B19: Instagram | C19: 45325 | D19: =IF( C19 < _xlfn.XLOOKUP(O19,'Campaign Metadata'!A:A,'Campaign Metadata'!B:B), "Before", IF( C19 <= _xlfn.XLOOKUP(O19,'Campaign Metadata'!A:A,'Campaign Metadata'!C:C), "During", "After" ) ) -> Before | E19: Story | F19: Music that moves youâ€”only on Spotify. | G19: 4281 | H19: 101 | I19: 163 | J19: 32278 | K19: 53382 | L19: 235 | M19: =(G19 +I19 +H19) / J19 -> 0.14080798 | N19: =G19+H19+I19 -> 4545 | O19: Wrapped2024 | P19: #NowPlaying
A20: SP019 | B20: YouTube | C20: 45458 | D20: =IF( C20 < _xlfn.XLOOKUP(O20,'Campaign Metadata'!A:A,'Campaign Metadata'!B:B), "Before", IF( C20 <= _xlfn.XLOOKUP(O20,'Campaign Metadata'!A:A,'Campaign Metadata'!C:C), "During", "After" ) ) -> During | E20: Reel | F20: Get into the groove with our new drop! | G20: 1751 | H20: 143 | I20: 151 | J20: 31826 | K20: 47729 | L20: 95 | M20: =(G20 +I20 +H20) / J20 -> 0.06425564 | N20: =G20+H20+I20 -> 2045 | O20: SummerBeats | P20: #DiscoverWeekly | Q20: #SoundtrackOfLife
A21: SP020 | B21: Instagram | C21: 45478 | D21: =IF( C21 < _xlfn.XLOOKUP(O21,'Campaign Metadata'!A:A,'Campaign Metadata'!B:B), "Before", IF( C21 <= _xlfn.XLOOKUP(O21,'Campaign Metadata'!A:A,'Campaign Metadata'!C:C), "During", "After" ) ) -> Before | E21: Text | F21: Your weekend playlist is waiting. | G21: 3753 | H21: 411 | I21: 308 | J21: 29138 | K21: 27678 | L21: 90 | M21: =(G21 +I21 +H21) / J21 -> 0.15347656 | N21: =G21+H21+I21 -> 4472 | O21: IndieWave | P21: #DiscoverWeekly
A22: SP021 | B22: Instagram | C22: 45603 | D22: =IF( C22 < _xlfn.XLOOKUP(O22,'Campaign Metadata'!A:A,'Campaign Metadata'!B:B), "Before", IF( C22 <= _xlfn.XLOOKUP(O22,'Campaign Metadata'!A:A,'Campaign Metadata'!C:C), "During", "After" ) ) -> Before | E22: Story | F22: Wrapped is here! Relive your top tracks ðŸŽ§ | G22: 1678 | H22: 423 | I22: 323 | J22: 55668 | K22: 37945 | L22: 230 | M22: =(G22 +I22 +H22) / J22 -> 0.043543867 | N22: =G22+H22+I22 -> 2424 | O22: Wrapped2024 | P22: #NowPlaying
A23: SP022 | B23: Instagram | C23: 45823 | D23: =IF( C23 < _xlfn.XLOOKUP(O23,'Campaign Metadata'!A:A,'Campaign Metadata'!B:B), "Before", IF( C23 <= _xlfn.XLOOKUP(O23,'Campaign Metadata'!A:A,'Campaign Metadata'!C:C), "During", "After" ) ) -> After | E23: Text | F23: Whatâ€™s your vibe today? #SpotifyHits | G23: 4896 | H23: 466 | I23: 233 | J23: 28621 | K23: 34270 | L23: 84 | M23: =(G23 +I23 +H23) / J23 -> 0.19548583 | N23: =G23+H23+I23 -> 5595 | O23: ChillVibes | P23: #SoundtrackOfLife | Q23: #NowPlaying
A24: SP023 | B24: YouTube | C24: 45452 | D24: =IF( C24 < _xlfn.XLOOKUP(O24,'Campaign Metadata'!A:A,'Campaign Metadata'!B:B), "Before", IF( C24 <= _xlfn.XLOOKUP(O24,'Campaign Metadata'!A:A,'Campaign Metadata'!C:C), "During", "After" ) ) -> Before | E24: Reel | F24: From pop to podcasts, itâ€™s all here. | G24: 2786 | H24: 368 | I24: 208 | J24: 42000 | K24: 39967 | L24: 103 | M24: =(G24 +I24 +H24) / J24 -> 0.080047619 | N24: =G24+H24+I24 -> 3362 | O24: SummerBeats | P24: #DiscoverWeekly | Q24: #SoundtrackOfLife
A25: SP024 | B25: Twitter | C25: 45583 | D25: =IF( C25 < _xlfn.XLOOKUP(O25,'Campaign Metadata'!A:A,'Campaign Metadata'!B:B), "Before", IF( C25 <= _xlfn.XLOOKUP(O25,'Campaign Metadata'!A:A,'Campaign Metadata'!C:C), "During", "After" ) ) -> Before | E25: Text | F25: New music just dropped. Hit play! | G25: 2607 | H25: 379 | I25: 180 | J25: 28712 | K25: 61620 | L25: 174 | M25: =(G25 +I25 +H25) / J25 -> 0.11026748 | N25: =G25+H25+I25 -> 3166 | O25: IndieWave | P25: #SoundtrackOfLife
A26: SP025 | B26: YouTube | C26: 45575 | D26: =IF( C26 < _xlfn.XLOOKUP(O26,'Campaign Metadata'!A:A,'Campaign Metadata'!B:B), "Before", IF( C26 <= _xlfn.XLOOKUP(O26,'Campaign Metadata'!A:A,'Campaign Metadata'!C:C), "During", "After" ) ) -> After | E26: Reel | F26: From pop to podcasts, itâ€™s all here. | G26: 4013 | H26: 320 | I26: 92 | J26: 54605 | K26: 60169 | L26: 232 | M26: =(G26 +I26 +H26) / J26 -> 0.081036535 | N26: =G26+H26+I26 -> 4425 | O26: SummerBeats | P26: #DiscoverWeekly | Q26: #SoundtrackOfLife
A27: SP026 | B27: Twitter | C27: 45791 | D27: =IF( C27 < _xlfn.XLOOKUP(O27,'Campaign Metadata'!A:A,'Campaign Metadata'!B:B), "Before", IF( C27 <= _xlfn.XLOOKUP(O27,'Campaign Metadata'!A:A,'Campaign Metadata'!C:C), "During", "After" ) ) -> After | E27: Story | F27: From pop to podcasts, itâ€™s all here. | G27: 2707 | H27: 103 | I27: 51 | J27: 55302 | K27: 18801 | L27: 147 | M27: =(G27 +I27 +H27) / J27 -> 0.051734114 | N27: =G27+H27+I27 -> 2861 | O27: ChillVibes | P27: #DiscoverWeekly | Q27: #MusicForEveryone
A28: SP027 | B28: Instagram | C28: 45625 | D28: =IF( C28 < _xlfn.XLOOKUP(O28,'Campaign Metadata'!A:A,'Campaign Metadata'!B:B), "Before", IF( C28 <= _xlfn.XLOOKUP(O28,'Campaign Metadata'!A:A,'Campaign Metadata'!C:C), "During", "After" ) ) -> Before | E28: Text | F28: Whatâ€™s your vibe today? #SpotifyHits | G28: 2824 | H28: 425 | I28: 274 | J28: 31004 | K28: 53488 | L28: 268 | M28: =(G28 +I28 +H28) / J28 -> 0.1136305 | N28: =G28+H28+I28 -> 3523 | O28: ChillVibes | P28: #SoundtrackOfLife | Q28: #NowPlaying
A29: SP028 | B29: YouTube | C29: 45356 | D29: =IF( C29 < _xlfn.XLOOKUP(O29,'Campaign Metadata'!A:A,'Campaign Metadata'!B:B), "Before", IF( C29 <= _xlfn.XLOOKUP(O29,'Campaign Metadata'!A:A,'Campaign Metadata'!C:C), "During", "After" ) ) -> Before | E29: Reel | F29: Explore the latest podcasts now. | G29: 3558 | H29: 314 | I29: 199 | J29: 49612 | K29: 53929 | L29: 206 | M29: =(G29 +I29 +H29) / J29 -> 0.08205676 | N29: =G29+H29+I29 -> 4071 | O29: SummerBeats | P29: #DiscoverWeekly | Q29: #SoundtrackOfLife
A30: SP029 | B30: Twitter | C30: 45734 | D30: =IF( C30 < _xlfn.XLOOKUP(O30,'Campaign Metadata'!A:A,'Campaign Metadata'!B:B), "Before", IF( C30 <= _xlfn.XLOOKUP(O30,'Campaign Metadata'!A:A,'Campaign Metadata'!C:C), "During", "After" ) ) -> After | E30: Story | F30: Explore the latest podcasts now. | G30: 3418 | H30: 188 | I30: 387 | J30: 57431 | K30: 36933 | L30: 202 | M30: =(G30 +I30 +H30) / J30 -> 0.069526911 | N30: =G30+H30+I30 -> 3993 | O30: ChillVibes | P30: #MusicForEveryone | Q30: #NowPlaying
A31: SP030 | B31: Twitter | C31: 45773 | D31: =IF( C31 < _xlfn.XLOOKUP(O31,'Campaign Metadata'!A:A,'Campaign Metadata'!B:B), "Before", IF( C31 <= _xlfn.XLOOKUP(O31,'Campaign Metadata'!A:A,'Campaign Metadata'!C:C), "During", "After" ) ) -> After | E31: Text | F31: Discover fresh beats on Spotify! | G31: 2411 | H31: 194 | I31: 168 | J31: 26665 | K31: 71699 | L31: 197 | M31: =(G31 +I31 +H31) / J31 -> 0.103994 | N31: =G31+H31+I31 -> 2773 | O31: ChillVibes | P31: #NowPlaying
A32: SP031 | B32: Instagram | C32: 45658 | D32: =IF( C32 < _xlfn.XLOOKUP(O32,'Campaign Metadata'!A:A,'Campaign Metadata'!B:B), "Before", IF( C32 <= _xlfn.XLOOKUP(O32,'Campaign Metadata'!A:A,'Campaign Metadata'!C:C), "During", "After" ) ) -> Before | E32: Text | F32: New music just dropped. Hit play! | G32: 4036 | H32: 112 | I32: 382 | J32: 56284 | K32: 29440 | L32: 279 | M32: =(G32 +I32 +H32) / J32 -> 0.080484685 | N32: =G32+H32+I32 -> 4530 | O32: ChillVibes | P32: #SoundtrackOfLife | Q32: #NowPlaying
A33: SP032 | B33: Twitter | C33: 45419 | D33: =IF( C33 < _xlfn.XLOOKUP(O33,'Campaign Metadata'!A:A,'Campaign Metadata'!B:B), "Before", IF( C33 <= _xlfn.XLOOKUP(O33,'Campaign Metadata'!A:A,'Campaign Metadata'!C:C), "During", "After" ) ) -> Before | E33: Story | F33: Explore the latest podcasts now. | G33: 2776 | H33: 307 | I33: 178 | J33: 43365 | K33: 48408 | L33: 138 | M33: =(G33 +I33 +H33) / J33 -> 0.075198893 | N33: =G33+H33+I33 -> 3261 | O33: ChillVibes | P33: #SoundtrackOfLife | Q33: #NowPlaying
A34: SP033 | B34: Twitter | C34: 45574 | D34: =IF( C34 < _xlfn.XLOOKUP(O34,'Campaign Metadata'!A:A,'Campaign Metadata'!B:B), "Before", IF( C34 <= _xlfn.XLOOKUP(O34,'Campaign Metadata'!A:A,'Campaign Metadata'!C:C), "During", "After" ) ) -> Before | E34: Story | F34: Discover fresh beats on Spotify! | G34: 4929 | H34: 182 | I34: 95 | J34: 32181 | K34: 31084 | L34: 289 | M34: =(G34 +I34 +H34) / J34 -> 0.16177247 | N34: =G34+H34+I34 -> 5206 | O34: ChillVibes | P34: #DiscoverWeekly | Q34: #MusicForEveryone
A35: SP034 | B35: Instagram | C35: 45666 | D35: =IF( C35 < _xlfn.XLOOKUP(O35,'Campaign Metadata'!A:A,'Campaign Metadata'!B:B), "Before", IF( C35 <= _xlfn.XLOOKUP(O35,'Campaign Metadata'!A:A,'Campaign Metadata'!C:C), "During", "After" ) ) -> Before | E35: Text | F35: New music just dropped. Hit play! | G35: 1015 | H35: 366 | I35: 308 | J35: 38127 | K35: 63790 | L35: 287 | M35: =(G35 +I35 +H35) / J35 -> 0.044299315 | N35: =G35+H35+I35 -> 1689 | O35: ChillVibes | P35: #SoundtrackOfLife | Q35: #NowPlaying
A36: SP035 | B36: Twitter | C36: 45785 | D36: =IF( C36 < _xlfn.XLOOKUP(O36,'Campaign Metadata'!A:A,'Campaign Metadata'!B:B), "Before", IF( C36 <= _xlfn.XLOOKUP(O36,'Campaign Metadata'!A:A,'Campaign Metadata'!C:C), "During", "After" ) ) -> After | E36: Story | F36: Your weekend playlist is waiting. | G36: 3316 | H36: 332 | I36: 268 | J36: 40095 | K36: 36913 | L36: 265 | M36: =(G36 +I36 +H36) / J36 -> 0.097668038 | N36: =G36+H36+I36 -> 3916 | O36: ChillVibes | P36: #MusicForEveryone | Q36: #NowPlaying
A37: SP036 | B37: Instagram | C37: 45416 | D37: =IF( C37 < _xlfn.XLOOKUP(O37,'Campaign Metadata'!A:A,'Campaign Metadata'!B:B), "Before", IF( C37 <= _xlfn.XLOOKUP(O37,'Campaign Metadata'!A:A,'Campaign Metadata'!C:C), "During", "After" ) ) -> Before | E37: Text | F37: Wrapped is here! Relive your top tracks ðŸŽ§ | G37: 2274 | H37: 243 | I37: 222 | J37: 43066 | K37: 59174 | L37: 80 | M37: =(G37 +I37 +H37) / J37 -> 0.063600056 | N37: =G37+H37+I37 -> 2739 | O37: IndieWave | P37: #DiscoverWeekly
A38: SP037 | B38: Twitter | C38: 45804 | D38: =IF( C38 < _xlfn.XLOOKUP(O38,'Campaign Metadata'!A:A,'Campaign Metadata'!B:B), "Before", IF( C38 <= _xlfn.XLOOKUP(O38,'Campaign Metadata'!A:A,'Campaign Metadata'!C:C), "During", "After" ) ) -> After | E38: Story | F38: Explore the latest podcasts now. | G38: 4095 | H38: 385 | I38: 400 | J38: 45300 | K38: 31795 | L38: 80 | M38: =(G38 +I38 +H38) / J38 -> 0.10772627 | N38: =G38+H38+I38 -> 4880 | O38: ChillVibes | P38: #MusicForEveryone | Q38: #NowPlaying
A39: SP038 | B39: Instagram | C39: 45545 | D39: =IF( C39 < _xlfn.XLOOKUP(O39,'Campaign Metadata'!A:A,'Campaign Metadata'!B:B), "Before", IF( C39 <= _xlfn.XLOOKUP(O39,'Campaign Metadata'!A:A,'Campaign Metadata'!C:C), "During", "After" ) ) -> Before | E39: Story | F39: New music just dropped. Hit play! | G39: 1230 | H39: 309 | I39: 207 | J39: 44629 | K39: 40699 | L39: 195 | M39: =(G39 +I39 +H39) / J39 -> 0.039122544 | N39: =G39+H39+I39 -> 1746 | O39: Wrapped2024 | P39: #NowPlaying
A40: SP039 | B40: Instagram | C40: 45621 | D40: =IF( C40 < _xlfn.XLOOKUP(O40,'Campaign Metadata'!A:A,'Campaign Metadata'!B:B), "Before", IF( C40 <= _xlfn.XLOOKUP(O40,'Campaign Metadata'!A:A,'Campaign Metadata'!C:C), "During", "After" ) ) -> Before | E40: Text | F40: From pop to podcasts, itâ€™s all here. | G40: 1341 | H40: 472 | I40: 238 | J40: 51386 | K40: 51706 | L40: 133 | M40: =(G40 +I40 +H40) / J40 -> 0.039913595 | N40: =G40+H40+I40 -> 2051 | O40: IndieWave | P40: #DiscoverWeekly
...

Sheet Campaign_Performance
A1: Row Labels | B1: Sum of Impressions | C1: Average of Impressions | D1: Average of Likes | E1: Sum of Likes | F1: Sum of Clicks | G1: Average of Clicks | I1: Campaign Performance
A2: ChillVibes | B2: 6331868 | C2: 41116.026 | D2: 3058.6623 | E2: 471034 | F2: 28708 | G2: 186.41558
A3: IndieWave | B3: 4039305 | C3: 42971.33 | D3: 2919.734 | E3: 274455 | F3: 18717 | G3: 199.11702 | I3: • ChillVibes generates the highest total engagement (551,989).
A4: SummerBeats | B4: 1233853 | C4: 42546.655 | D4: 3099 | E4: 89871 | F4: 5557 | G4: 191.62069 | I4: • IndieWave shows strong engagement with solid click performance.
A5: Wrapped2024 | B5: 865406 | C5: 37626.348 | D5: 2687.6087 | E5: 61815 | F5: 4614 | G5: 200.6087 | I5: • SummerBeats underperforms compared to other campaigns.
A6: Grand Total | B6: 12470432 | C6: 41568.107 | D6: 2990.5833 | E6: 897175 | F6: 57596 | G6: 191.98667

Sheet Engagement Uplift
A1: Average of Engagment Rate | B1: Column Labels | F1: Engagement Uplift
A2: Row Labels | B2: After | C2: Before | D2: During | E2: Grand Total
A3: ChillVibes | B3: 0.096937629 | C3: 0.092728032 | D3: 0.1208618 | E3: 0.095830989 | F3: =GETPIVOTDATA("Engagment Rate",$A$1,"Campaign Phase","During","Campaign_Name","ChillVibes")-GETPIVOTDATA("Engagment Rate",$A$1,"Campaign Phase","Before","Campaign_Name","ChillVibes") -> 0.028133771
A4: IndieWave | B4: 0.085210186 | C4: 0.086673079 | D4: 0.11095871 | E4: 0.088052036 | F4: =GETPIVOTDATA("Engagment Rate",$A$1,"Campaign Phase","During","Campaign_Name","IndieWave")-GETPIVOTDATA("Engagment Rate",$A$1,"Campaign Phase","Before","Campaign_Name","IndieWave") -> 0.024285633 | H4: • ChillVibes and IndieWave show positive engagement uplift during campaign period.
A5: SummerBeats | B5: 0.083934545 | C5: 0.097485783 | D5: 0.078574757 | E5: 0.090106882 | F5: =GETPIVOTDATA("Engagment Rate",$A$1,"Campaign Phase","During","Campaign_Name","SummerBeats")-GETPIVOTDATA("Engagment Rate",$A$1,"Campaign Phase","Before","Campaign_Name","SummerBeats") -> -0.018911027 | H5: • SummerBeats shows negative uplift, indicating campaign inefficiency.
A6: Wrapped2024 | B6: 0.1047681 | C6: 0.08707445 | D6: 0.095604953 | E6: 0.095509124 | F6: =GETPIVOTDATA("Engagment Rate",$A$1,"Campaign Phase","During","Campaign_Name","Wrapped2024")-GETPIVOTDATA("Engagment Rate",$A$1,"Campaign Phase","Before","Campaign_Name","Wrapped2024") -> 0.0085305033 | H6: • Wrapped2024 demonstrates moderate improvement.
A7: Grand Total | B7: 0.093968206 | C7: 0.090475289 | D7: 0.1115996 | E7: 0.092815577

Sheet Campaign ROI
A1: Row Labels | B1: Sum of Total Engagment | C1: Row Labels | D1: Sum of Ad_Spend | E1: Engagement per ₹-ROI | F1: RANK
A2: ChillVibes | B2: 551989 | C2: ChillVibes | D2: 201460 | E2: =GETPIVOTDATA("Total Engagment",$A$1,"Campaign_Name","ChillVibes")/GETPIVOTDATA("Ad_Spend",$C$1,"Campaign_Name","ChillVibes") -> 2.7399434 | F2: =RANK(E2,$E$2:$E$5,0) -> 1 | H2: • ChillVibes achieves the highest ROI (~2.74), delivering strong engagement per ₹ spent.
A3: IndieWave | B3: 324406 | C3: IndieWave | D3: 246330 | E3: =GETPIVOTDATA("Total Engagment",$A$1,"Campaign_Name","IndieWave")/GETPIVOTDATA("Ad_Spend",$C$1,"Campaign_Name","IndieWave") -> 1.3169569 | F3: =RANK(E3,$E$2:$E$5,0) -> 2 | H3: • IndieWave also shows strong ROI (~1.32).
A4: SummerBeats | B4: 105783 | C4: SummerBeats | D4: 252741 | E4: =GETPIVOTDATA("Total Engagment",$A$1,"Campaign_Name","SummerBeats")/GETPIVOTDATA("Ad_Spend",$C$1,"Campaign_Name","SummerBeats") -> 0.41854309 | F4: =RANK(E4,$E$2:$E$5,0) -> 3 | H4: • SummerBeats and Wrapped2024 have comparatively lower efficiency.
A5: Wrapped2024 | B5: 75464 | C5: Wrapped2024 | D5: 243827 | E5: =GETPIVOTDATA("Total Engagment",$A$1,"Campaign_Name","Wrapped2024")/GETPIVOTDATA("Ad_Spend",$C$1,"Campaign_Name","Wrapped2024") -> 0.30949813 | F5: =RANK(E5,$E$2:$E$5,0) -> 4 | H5: • ROI analysis indicates spending effectiveness varies significantly across campaigns.
A6: Grand Total | B6: 1057642 | C6: Grand Total | D6: 944358

Sheet Engagement Summary
A1: Week_Start_Date | B1: Platform | C1: New_Followers | D1: Unfollows | E1: Total_Followers | F1: Engagment Rate | G1: Ad_Spend | H1: Campaign_Name
A2: 45446 | B2: Instagram | C2: 1402 | D2: 68 | E2: 124562 | F2: 0.0992 | G2: 23125 | H2: {=IFERROR( INDEX('Campaign Metadata'!A:A, MATCH(1, (A2>='Campaign Metadata'!B:B)* (A2<='Campaign Metadata'!C:C), 0) ), "Non-Campaign")} -> Non-Campaign
A3: 45446 | B3: Twitter | C3: 995 | D3: 86 | E3: 227958 | F3: 0.0805 | G3: 22788 | H3: {=IFERROR( INDEX('Campaign Metadata'!A:A, MATCH(1, (A3>='Campaign Metadata'!B:B)* (A3<='Campaign Metadata'!C:C), 0) ), "Non-Campaign")} -> Non-Campaign
A4: 45446 | B4: YouTube | C4: 1472 | D4: 296 | E4: 370242 | F4: 0.0772 | G4: 7810 | H4: {=IFERROR( INDEX('Campaign Metadata'!A:A, MATCH(1, (A4>='Campaign Metadata'!B:B)* (A4<='Campaign Metadata'!C:C), 0) ), "Non-Campaign")} -> Non-Campaign
A5: 45453 | B5: Instagram | C5: 1018 | D5: 90 | E5: 92474 | F5: 0.094 | G5: 11966 | H5: {=IFERROR( INDEX('Campaign Metadata'!A:A, MATCH(1, (A5>='Campaign Metadata'!B:B)* (A5<='Campaign Metadata'!C:C), 0) ), "Non-Campaign")} -> Non-Campaign
A6: 45453 | B6: Twitter | C6: 1461 | D6: 64 | E6: 328902 | F6: 0.0902 | G6: 26298 | H6: {=IFERROR( INDEX('Campaign Metadata'!A:A, MATCH(1, (A6>='Campaign Metadata'!B:B)* (A6<='Campaign Metadata'!C:C), 0) ), "Non-Campaign")} -> Non-Campaign
A7: 45453 | B7: YouTube | C7: 545 | D7: 93 | E7: 391621 | F7: 0.0996 | G7: 22029 | H7: {=IFERROR( INDEX('Campaign Metadata'!A:A, MATCH(1, (A7>='Campaign Metadata'!B:B)* (A7<='Campaign Metadata'!C:C), 0) ), "Non-Campaign")} -> Non-Campaign
A8: 45460 | B8: Instagram | C8: 881 | D8: 291 | E8: 95885 | F8: 0.0529 | G8: 12391 | H8: {=IFERROR( INDEX('Campaign Metadata'!A:A, MATCH(1, (A8>='Campaign Metadata'!B:B)* (A8<='Campaign Metadata'!C:C), 0) ), "Non-Campaign")} -> SummerBeats
A9: 45460 | B9: Twitter | C9: 1414 | D9: 131 | E9: 245947 | F9: 0.083 | G9: 14477 | H9: {=IFERROR( INDEX('Campaign Metadata'!A:A, MATCH(1, (A9>='Campaign Metadata'!B:B)* (A9<='Campaign Metadata'!C:C), 0) ), "Non-Campaign")} -> SummerBeats
A10: 45460 | B10: YouTube | C10: 1472 | D10: 170 | E10: 250428 | F10: 0.0466 | G10: 25040 | H10: {=IFERROR( INDEX('Campaign Metadata'!A:A, MATCH(1, (A10>='Campaign Metadata'!B:B)* (A10<='Campaign Metadata'!C:C), 0) ), "Non-Campaign")} -> SummerBeats
A11: 45467 | B11: Instagram | C11: 809 | D11: 197 | E11: 87186 | F11: 0.0948 | G11: 22619 | H11: {=IFERROR( INDEX('Campaign Metadata'!A:A, MATCH(1, (A11>='Campaign Metadata'!B:B)* (A11<='Campaign Metadata'!C:C), 0) ), "Non-Campaign")} -> SummerBeats
A12: 45467 | B12: Twitter | C12: 1371 | D12: 250 | E12: 128620 | F12: 0.0711 | G12: 12399 | H12: {=IFERROR( INDEX('Campaign Metadata'!A:A, MATCH(1, (A12>='Campaign Metadata'!B:B)* (A12<='Campaign Metadata'!C:C), 0) ), "Non-Campaign")} -> SummerBeats
A13: 45467 | B13: YouTube | C13: 844 | D13: 144 | E13: 126015 | F13: 0.0965 | G13: 22456 | H13: {=IFERROR( INDEX('Campaign Metadata'!A:A, MATCH(1, (A13>='Campaign Metadata'!B:B)* (A13<='Campaign Metadata'!C:C), 0) ), "Non-Campaign")} -> SummerBeats
A14: 45474 | B14: Instagram | C14: 786 | D14: 72 | E14: 178615 | F14: 0.0543 | G14: 19328 | H14: {=IFERROR( INDEX('Campaign Metadata'!A:A, MATCH(1, (A14>='Campaign Metadata'!B:B)* (A14<='Campaign Metadata'!C:C), 0) ), "Non-Campaign")} -> SummerBeats
A15: 45474 | B15: Twitter | C15: 845 | D15: 250 | E15: 218228 | F15: 0.0452 | G15: 21107 | H15: {=IFERROR( INDEX('Campaign Metadata'!A:A, MATCH(1, (A15>='Campaign Metadata'!B:B)* (A15<='Campaign Metadata'!C:C), 0) ), "Non-Campaign")} -> SummerBeats | N15: D
A16: 45474 | B16: YouTube | C16: 1218 | D16: 101 | E16: 300397 | F16: 0.0433 | G16: 12277 | H16: {=IFERROR( INDEX('Campaign Metadata'!A:A, MATCH(1, (A16>='Campaign Metadata'!B:B)* (A16<='Campaign Metadata'!C:C), 0) ), "Non-Campaign")} -> SummerBeats
A17: 45481 | B17: Instagram | C17: 797 | D17: 130 | E17: 340121 | F17: 0.0852 | G17: 11684 | H17: {=IFERROR( INDEX('Campaign Metadata'!A:A, MATCH(1, (A17>='Campaign Metadata'!B:B)* (A17<='Campaign Metadata'!C:C), 0) ), "Non-Campaign")} -> SummerBeats
A18: 45481 | B18: Twitter | C18: 1471 | D18: 100 | E18: 76866 | F18: 0.0855 | G18: 14412 | H18: {=IFERROR( INDEX('Campaign Metadata'!A:A, MATCH(1, (A18>='Campaign Metadata'!B:B)* (A18<='Campaign Metadata'!C:C), 0) ), "Non-Campaign")} -> SummerBeats
A19: 45481 | B19: YouTube | C19: 1253 | D19: 136 | E19: 193131 | F19: 0.0799 | G19: 15924 | H19: {=IFERROR( INDEX('Campaign Metadata'!A:A, MATCH(1, (A19>='Campaign Metadata'!B:B)* (A19<='Campaign Metadata'!C:C), 0) ), "Non-Campaign")} -> SummerBeats
A20: 45488 | B20: Instagram | C20: 616 | D20: 257 | E20: 169665 | F20: 0.0631 | G20: 12390 | H20: {=IFERROR( INDEX('Campaign Metadata'!A:A, MATCH(1, (A20>='Campaign Metadata'!B:B)* (A20<='Campaign Metadata'!C:C), 0) ), "Non-Campaign")} -> SummerBeats
A21: 45488 | B21: Twitter | C21: 1308 | D21: 210 | E21: 263729 | F21: 0.0853 | G21: 25742 | H21: {=IFERROR( INDEX('Campaign Metadata'!A:A, MATCH(1, (A21>='Campaign Metadata'!B:B)* (A21<='Campaign Metadata'!C:C), 0) ), "Non-Campaign")} -> SummerBeats
A22: 45488 | B22: YouTube | C22: 981 | D22: 69 | E22: 206921 | F22: 0.0842 | G22: 10495 | H22: {=IFERROR( INDEX('Campaign Metadata'!A:A, MATCH(1, (A22>='Campaign Metadata'!B:B)* (A22<='Campaign Metadata'!C:C), 0) ), "Non-Campaign")} -> SummerBeats
A23: 45495 | B23: Instagram | C23: 866 | D23: 74 | E23: 204121 | F23: 0.0934 | G23: 7797 | H23: {=IFERROR( INDEX('Campaign Metadata'!A:A, MATCH(1, (A23>='Campaign Metadata'!B:B)* (A23<='Campaign Metadata'!C:C), 0) ), "Non-Campaign")} -> Non-Campaign
A24: 45495 | B24: Twitter | C24: 547 | D24: 183 | E24: 266350 | F24: 0.0565 | G24: 15595 | H24: {=IFERROR( INDEX('Campaign Metadata'!A:A, MATCH(1, (A24>='Campaign Metadata'!B:B)* (A24<='Campaign Metadata'!C:C), 0) ), "Non-Campaign")} -> Non-Campaign
A25: 45495 | B25: YouTube | C25: 1241 | D25: 116 | E25: 380606 | F25: 0.042 | G25: 24617 | H25: {=IFERROR( INDEX('Campaign Metadata'!A:A, MATCH(1, (A25>='Campaign Metadata'!B:B)* (A25<='Campaign Metadata'!C:C), 0) ), "Non-Campaign")} -> Non-Campaign
A26: 45502 | B26: Instagram | C26: 973 | D26: 104 | E26: 376358 | F26: 0.0387 | G26: 9847 | H26: {=IFERROR( INDEX('Campaign Metadata'!A:A, MATCH(1, (A26>='Campaign Metadata'!B:B)* (A26<='Campaign Metadata'!C:C), 0) ), "Non-Campaign")} -> Non-Campaign
A27: 45502 | B27: Twitter | C27: 611 | D27: 197 | E27: 79423 | F27: 0.0582 | G27: 13644 | H27: {=IFERROR( INDEX('Campaign Metadata'!A:A, MATCH(1, (A27>='Campaign Metadata'!B:B)* (A27<='Campaign Metadata'!C:C), 0) ), "Non-Campaign")} -> Non-Campaign
... A201: 45908 | B201: Twitter | C201: 860 | D201: 244 | E201: 348686 | F201: 0.0512 | G201: 11418 | H201: {=IFERROR( INDEX('Campaign Metadata'!A:A, MATCH(1, (A201>='Campaign Metadata'!B:B)* (A201<='Campaign Metadata'!C:C), 0) ), "Non-Campaign")} -> Non-Campaign
